Workbook

Sheet Plano
A1: ID do plano | B1: Nome do plano | C1: Data da exportação
A2: fHewUC8uj0ioRbpAX8PFEmQADhut | B2: Gestão MEG | C2: 2026-08-15

Sheet Dados Consolidados
A1: Identificação da tarefa | B1: Nome da tarefa | C1: Categoria | D1: Meta | E1: Status | F1: Prioridade | G1: Atribuído a | H1: Criado por | I1: Criado em | J1: Data de conclusão | K1: Data de início | L1: É Recorrente | M1: Atrasados | N1: Concluído em | O1: Concluída por | P1: Itens concluídos da lista de verificação | Q1: Itens da lista de verificação | R1: Rótulos | S1: Notas | T1: Orçamento
A2: mHYaQDYxrUiQ7uHDBJV_CGQAA0Bm | B2: Lançar melhoria do bimestre | C2: =_xlfn.XLOOKUP(A2,Tarefas!A:A,Tarefas!C:C) -> Programa de Melhorias | E2: Não iniciado | F2: Média | G2: Francisco Romulo de Aguiar;;William Kennedy Rodrigues Lopes;Francisco Martins da Silva;Charliane Batista de Alencar | H2: Francisco Romulo de Aguiar | I2: 2026-08-06 | J2: 2026-10-05 | M2: false | P2: 0/10 | Q2: Rômulo ;Charliane;Thiago Roberto;Martins;Leonardo Galdino;Kennedy;Leonardo Costa;Eduarda;Daniel Viana;Alan Vilela | T2: 880.64
A3: epEHIZFoYEawEMf2UmdnO2QAEl9u | B3: Lançar melhoria do bimestre | C3: =_xlfn.XLOOKUP(A3,Tarefas!A:A,Tarefas!C:C) -> Programa de Melhorias | E3: Concluída | F3: Média | G3: Francisco Romulo de Aguiar;;William Kennedy Rodrigues Lopes;Francisco Martins da Silva;Charliane Batista de Alencar | H3: Fernanda Sousa Araujo | I3: 2026-07-17 | J3: 2026-08-05 | M3: false | N3: 2026-08-06 | O3: Francisco Romulo de Aguiar | P3: 7/10 | Q3: Rômulo ;Charliane;Thiago Roberto;Martins;Leonardo Galdino;Kennedy;Leonardo Costa;Eduarda;Daniel Viana;Alan Vilela | T3: 321.55
A4: 7SBLlTg6NUODyqgmnqwBnmQAPYN6 | B4: Lançar melhoria do bimestre | C4: =_xlfn.XLOOKUP(A4,Tarefas!A:A,Tarefas!C:C) -> Programa de Melhorias | E4: Concluída | F4: Média | G4: Francisco Romulo de Aguiar;;;William Kennedy Rodrigues Lopes;Francisco Martins da Silva;Charliane Batista de Alencar | H4: Fernanda Sousa Araujo | I4: 2026-07-17 | J4: 2026-04-05 | M4: false | N4: 2026-07-17 | O4: Fernanda Sousa Araujo | P4: 0/6 | Q4: Rômulo ;Charliane;Martins;Kennedy;Douglas;Jennifer | T4: 560.77
A5: DRYwgOUmRUOgKzjzalMjq2QAAtiM | B5: Lançar melhoria do bimestre | C5: =_xlfn.XLOOKUP(A5,Tarefas!A:A,Tarefas!C:C) -> Programa de Melhorias | E5: Concluída | F5: Média | G5: Francisco Romulo de Aguiar;;;William Kennedy Rodrigues Lopes;Francisco Martins da Silva;Charliane Batista de Alencar | H5: Fernanda Sousa Araujo | I5: 2026-07-17 | J5: 2026-02-05 | M5: false | N5: 2026-07-17 | O5: Fernanda Sousa Araujo | P5: 0/6 | Q5: Rômulo ;Charliane;Martins;Kennedy;Douglas;Jennifer | T5: 755.5
A6: F1LFUkS0RUu3Ibi25ZzRWWQAJj2X | B6: Lançar melhoria do bimestre | C6: =_xlfn.XLOOKUP(A6,Tarefas!A:A,Tarefas!C:C) -> Programa de Melhorias | E6: Concluída | F6: Média | G6: Francisco Romulo de Aguiar;;;William Kennedy Rodrigues Lopes;Francisco Martins da Silva;Charliane Batista de Alencar | H6: Fernanda Sousa Araujo | I6: 2026-07-17 | J6: 2025-12-05 | M6: false | N6: 2026-07-17 | O6: Fernanda Sousa Araujo | P6: 0/6 | Q6: Rômulo ;Charliane;Martins;Kennedy;Douglas;Jennifer | T6: 349.29
A7: uQH-ZMJsr0CX1CPaui9Al2QAA1wN | B7: Lançar melhoria do bimestre | C7: =_xlfn.XLOOKUP(A7,Tarefas!A:A,Tarefas!C:C) -> Programa de Melhorias | E7: Concluída | F7: Média | G7: Francisco Romulo de Aguiar;;;William Kennedy Rodrigues Lopes;Francisco Martins da Silva;Charliane Batista de Alencar | H7: Fernanda Sousa Araujo | I7: 2026-07-17 | J7: 2025-10-05 | M7: false | N7: 2026-07-17 | O7: Fernanda Sousa Araujo | P7: 0/6 | Q7: Rômulo ;Charliane;Martins;Kennedy;Douglas;Jennifer | T7: 285
A8: txeRybaODEq_PH978neS1mQAGaS0 | B8: Lançar melhoria do bimestre | C8: =_xlfn.XLOOKUP(A8,Tarefas!A:A,Tarefas!C:C) -> Programa de Melhorias | E8: Concluída | F8: Média | G8: Francisco Romulo de Aguiar;;;William Kennedy Rodrigues Lopes;Francisco Martins da Silva;Charliane Batista de Alencar | H8: Fernanda Sousa Araujo | I8: 2026-07-17 | J8: 2025-08-08 | M8: false | N8: 2026-07-17 | O8: Fernanda Sousa Araujo | P8: 0/6 | Q8: Rômulo ;Charliane;Martins;Kennedy;Douglas;Jennifer | T8: 502.98
A9: tygljY6P00iU4kfls2vKV2QAG4Zo | B9: Lançar melhoria do bimestre | C9: =_xlfn.XLOOKUP(A9,Tarefas!A:A,Tarefas!C:C) -> Programa de Melhorias | E9: Concluída | F9: Média | G9: Francisco Romulo de Aguiar;;;William Kennedy Rodrigues Lopes;Francisco Martins da Silva;Charliane Batista de Alencar | H9: Fernanda Sousa Araujo | I9: 2026-07-17 | J9: 2024-12-05 | M9: false | N9: 2026-07-17 | O9: Fernanda Sousa Araujo | P9: 0/6 | Q9: Rômulo ;Charliane;Martins;Kennedy;Douglas;Jennifer | T9: 110.46
A10: 22BLBarPRUGDpRVdEMXK-WQAIPMG | B10: Lançar melhoria do bimestre | C10: =_xlfn.XLOOKUP(A10,Tarefas!A:A,Tarefas!C:C) -> Programa de Melhorias | E10: Concluída | F10: Média | G10: Francisco Romulo de Aguiar;;;William Kennedy Rodrigues Lopes;Francisco Martins da Silva;Charliane Batista de Alencar | H10: Fernanda Sousa Araujo | I10: 2024-07-05 | J10: 2024-10-31 | M10: false | N10: 2026-07-17 | O10: Fernanda Sousa Araujo | P10: 0/6 | Q10: Rômulo ;Charliane;Martins;Kennedy;Douglas;Jennifer | T10: 32.19
A11: XyQwFCHhokWxK8Qtp4qmkmQADVuN | B11: Fazer auditoria nos postos de trabalho dos lançamentos | C11: =_xlfn.XLOOKUP(A11,Tarefas!A:A,Tarefas!C:C) -> Tarefas Antigas | E11: Concluída | F11: Média | H11: Fernanda Sousa Araujo | I11: 2024-07-25 | J11: 2024-08-30 | M11: false | N11: 2024-09-05 | P11: 4/4 | Q11: Gerar laudo dos postos de trabalho e enviar para os envolvidos ;Registrar condições dos postos com fotos ;Analisar postos nos pilares de P5.0 e Ergonomia ;Passar nas linhas produtivas dos lançamentos | R11: Rotina | T11: 391.93
A12: Hl4x_KZhpkyOUlv5RxATVGQAM31J | B12: Criar as documentações do TEGAD dentro matrix | C12: =_xlfn.XLOOKUP(A12,Tarefas!A:A,Tarefas!C:C) -> Tarefas Antigas | E12: Concluída | F12: Média | H12: Fernanda Sousa Araujo | I12: 2024-07-25 | J12: 2024-08-02 | M12: false | N12: 2024-08-10 | T12: 52.13
A13: UjbIJMabvEC4WDGe9hiHvWQAK3Mj | B13: Criar as documentações dos montadores de layout dentro do matrix | C13: =_xlfn.XLOOKUP(A13,Tarefas!A:A,Tarefas!C:C) -> Tarefas Antigas | E13: Concluída | F13: Média | H13: Fernanda Sousa Araujo | I13: 2024-07-25 | J13: 2024-09-13 | M13: false | N13: 2026-07-17 | O13: Fernanda Sousa Araujo | T13: 173.06
A14: OxRSVcPgZEuV9LODx_vat2QAPkqZ | B14: Work sampling no processo de chamada ativa do PS7 | C14: =_xlfn.XLOOKUP(A14,Tarefas!A:A,Tarefas!C:C) -> Tarefas Antigas | E14: Concluída | F14: Média | G14: ; | H14: Fernanda Sousa Araujo | I14: 2024-07-25 | J14: 2024-08-23 | M14: false | N14: 2024-08-20 | P14: 4/4 | Q14: Gerar um gráfico com os dados de percurso com maior repetição ;Registrar os percursos realizados de movimentação dos operadores ;Acompanhar o processo ;Anotar as ocorrências ou divergências do processo | T14: 96.29
A15: kTIeuZuHKk6LutwStQOPmWQAKOcl | B15: Cadastro de pessoas treinadas aplicativo. | C15: =_xlfn.XLOOKUP(A15,Tarefas!A:A,Tarefas!C:C) -> Tarefas Antigas | E15: Concluída | F15: Média | G15: ; | I15: 2024-07-25 | J15: 2024-08-23 | M15: false | N15: 2024-08-20 | S15: Cadastrar listas de pessoas treinadas no aplicativo. | T15: 318.55
A16: HgnLevcgA0qC8e0NaziGdmQAAQrK | B16: Atualização planilhas SMED e criação de boletim. | C16: =_xlfn.XLOOKUP(A16,Tarefas!A:A,Tarefas!C:C) -> Tarefas Antigas | E16: Concluída | F16: Média | G16: ;William Kennedy Rodrigues Lopes | I16: 2024-08-12 | J16: 2024-08-23 | M16: false | N16: 2024-08-20 | T16: 0.98
A17: xZIuz0fqHEKGRIVvx_CjpGQAApIE | B17: Desenho | C17: =_xlfn.XLOOKUP(A17,Tarefas!A:A,Tarefas!C:C) -> Tarefas Antigas | E17: Concluída | F17: Média | I17: 2024-08-13 | J17: 2024-08-16 | M17: false | N17: 2024-08-13 | P17: 3/3 | Q17: Desenho da Mesa Posto de trabalho F3;Desenho do Layout F3-F4;Desenho do Layout Peças Técnicas | T17: 274.44
A18: lDsMV28xPka_W5yxSGhSB2QAJ3v7 | B18: Atualização planilha dos indicadores | C18: =_xlfn.XLOOKUP(A18,Tarefas!A:A,Tarefas!C:C) -> Tarefas Antigas | E18: Concluída | F18: Média | G18: ; | I18: 2024-08-20 | J18: 2024-08-21 | M18: false | N18: 2024-08-22 | T18: 210.98
A19: 8ZiKOBm8V0W1aszegn2HImQAO_b_ | B19: Atualizar checklist kaizen, ver com RH cadastro de pessoas treinadas em Kaizen. | C19: =_xlfn.XLOOKUP(A19,Tarefas!A:A,Tarefas!C:C) -> Tarefas Antigas | E19: Concluída | F19: Média | G19: ; | I19: 2024-08-20 | J19: 2024-08-21 | M19: false | N19: 2024-08-21 | T19: 389.75
A20: H1uUhGXRGU-77B3fs6q8LmQANBpP | B20: Organização materiais MEG | C20: =_xlfn.XLOOKUP(A20,Tarefas!A:A,Tarefas!C:C) -> Tarefas Antigas | E20: Concluída | F20: Média | G20: ; | I20: 2024-08-20 | J20: 2024-09-12 | M20: false | N20: 2026-07-17 | O20: Fernanda Sousa Araujo | T20: 499.61
A21: 1jM1QpSMA02fNwk_HDPi_mQAKDS8 | B21: Estudo Sala Impressão Digital | C21: =_xlfn.XLOOKUP(A21,Tarefas!A:A,Tarefas!C:C) -> Tarefas Antigas | E21: Concluída | F21: Média | I21: 2024-08-20 | J21: 2024-09-18 | M21: false | N21: 2026-07-17 | O21: Fernanda Sousa Araujo | T21: 612.74
A22: cQO-fezfA0eUz3P6IidJkGQABDk8 | B22: Organizar evento de melhorias | C22: =_xlfn.XLOOKUP(A22,Tarefas!A:A,Tarefas!C:C) -> Tarefas Antigas | E22: Concluída | F22: Média | H22: Fernanda Sousa Araujo | I22: 2024-09-27 | J22: 2024-09-24 | M22: false | N22: 2024-09-27 | O22: Fernanda Sousa Araujo | P22: 5/5 | Q22: Organizar o espaço de eventos ;Montar apresentação do evento ;Listar os dados dos premiados (Calçados e informações gerais);Levantar dados das avaliações de percepção. ;Treinar a apresentação | T22: 273.08
A23: SZ2NF2FBAE-UeRtXURXbLmQANNYa | B23: Passada Horizontal no TS6 | C23: =_xlfn.XLOOKUP(A23,Tarefas!A:A,Tarefas!C:C) -> Tarefas Antigas | E23: Concluída | F23: Média | H23: Fernanda Sousa Araujo | I23: 2024-09-27 | J23: 2024-09-27 | M23: false | N23: 2024-09-27 | O23: Fernanda Sousa Araujo | T23: 793.53
A24: DjnKbRcTlEar2AF5aYS1g2QAJm8W | B24: Passada Horizontal TS7 | C24: =_xlfn.XLOOKUP(A24,Tarefas!A:A,Tarefas!C:C) -> Tarefas Antigas | E24: Concluída | F24: Média | H24: Fernanda Sousa Araujo | I24: 2024-09-27 | J24: 2024-09-25 | M24: false | N24: 2024-09-27 | O24: Fernanda Sousa Araujo | T24: 987.87
A25: LQZZqn7VwUm8GsQfpC4GhGQADMSP | B25: MOI - Movimentadores de Caixas Montagem | C25: =_xlfn.XLOOKUP(A25,Tarefas!A:A,Tarefas!C:C) -> MOI, MOA, MODS | D25: Redução de 50 efetivos MOA, MOI e MODS | E25: Em andamento | F25: Importante | G25: Charliane Batista de Alencar | H25: Charliane Batista de Alencar | I25: 2026-07-17 | J25: 2026-07-24 | K25: 2026-07-06 | M25: true | P25: 6/8 | Q25: Validar com a gestão;Determinar padrões da operações;Testar nova proposta;Verificar possíveis propostas de melhorias ou automações;Avaliar durante uma semana dimensionamento pro fator X Padrão / aglutinado;Lançar FAP;Criar nova proposta de dimensionamento;Levantar situação atual | R25: Crato | T25: 74.97
A26: NkewH3A-5Eail--FODKxU2QAH1YF | B26: Otimização Setup Matriz EVA | C26: =_xlfn.XLOOKUP(A26,Tarefas!A:A,Tarefas!C:C) -> SMED | D26: Redução de 25% do tempo de setup de matriz e 15% setup de cor na injeção de EVA | E26: Não iniciado | F26: Média | G26: Francisco Romulo de Aguiar;Aliny Kelly De Assis Rufino | H26: Francisco Romulo de Aguiar | I26: 2026-07-17 | J26: 2026-08-31 | K26: 2026-07-20 | M26: false | P26: 5/9 | Q26: Acompanhar definição do carrinho compra ou confecção junto a fábrica;Análise de ganho para transformação das matrizes em troca rápida (Vagner).;Análise de setups Matriz. (20 à 24/07);Acompanhamento de implantação do Simon.;Teste de carrinho com capacidade para matrizes de entrada e saída.;Fazer analise do custo da estufa ligada o dia todo (Setups por maquina e por dia);Teste de pré aquecimento de matriz em setups reais.;Análise do fluxo de programação do EVA.;Montar material para reunião com Igor (sobre a estufa e moer purga) | T26: 426.94
A27: sNUu7Jc6NkyzqxvlG4HlcGQANkch | B27: Cerimônia de Premiação do Programa de Melhorias | C27: =_xlfn.XLOOKUP(A27,Tarefas!A:A,Tarefas!C:C) -> Programa de Melhorias | E27: Em andamento | F27: Média | G27: Leonardo Costa da Silva | H27: Leonardo Costa da Silva | I27: 2026-07-17 | J27: 2026-12-31 | M27: false | P27: 1/4 | Q27: Cerimônia de Premiação - Bimestre Set/Out 2026;Cerimônia de Premiação - Bimestre Jul/Ago 2026;Cerimônia de Premiação - Bimestre Mai/Jun 2026;Cerimônia de Premiação - Bimestre Nov/Dez 2026 | T27: 244.88
A28: Rs5Oc-Bkx02tuG9Y-sk0lGQAMxXl | B28: MOI - Auxiliar de Matrizaria | C28: =_xlfn.XLOOKUP(A28,Tarefas!A:A,Tarefas!C:C) -> MOI, MOA, MODS | D28: Redução de 50 efetivos MOA, MOI e MODS | E28: Em andamento | F28: Importante | G28: Charliane Batista de Alencar | H28: Charliane Batista de Alencar | I28: 2026-07-17 | J28: 2026-07-22 | K28: 2026-07-06 | M28: true | P28: 9/10 | Q28: Validar com a gestão;Tabulação de dados e classificação das atividades;Acompanhar turno B;Apresentar a gerência e coordenação;Verificar possíveis propostas de melhorias, transferências ou otimização de atividades;Colocar em teste para avaliar;Proposta de novo dimensionamento;Verificar com Kleilson a decisão de alterar dimensionamento, conforme avaliação no físico;Lançar FAP;Acompanhamento turno A (07/07 e 09/07) | R28: Crato | T28: 273.43
A29: t8_qJepIiUqnTdiC4yZkT2QAI7ze | B29: MOI - Matrizeiro | C29: =_xlfn.XLOOKUP(A29,Tarefas!A:A,Tarefas!C:C) -> MOI, MOA, MODS | D29: Redução de 50 efetivos MOA, MOI e MODS | E29: Não iniciado | F29: Importante | H29: Charliane Batista de Alencar | I29: 2026-07-17 | M29: false | P29: 0/8 | Q29: Tabulação de dados e classificação das atividades;Proposta de novo dimensionamento;Colocar em teste para avaliar;Validar com a gestão;Acompanhamento turno A;Acompanhar turno B;Lançar FAP;Verificar possíveis propostas de melhorias, transferências ou otimização de atividades | R29: Crato | T29: 719.5
A30: XD1eWNDN_ECyHQuAr9pQImQAJevi | B30: SMED Setup de Cor EVA | C30: =_xlfn.XLOOKUP(A30,Tarefas!A:A,Tarefas!C:C) -> SMED | D30: Redução de 25% do tempo de setup de matriz e 15% setup de cor na injeção de EVA | E30: Não iniciado | F30: Média | G30: Francisco Romulo de Aguiar;Aliny Kelly De Assis Rufino | H30: Francisco Romulo de Aguiar | I30: 2026-07-17 | J30: 2026-10-31 | M30: false | P30: 5/7 | Q30: Análise da troca de cor sem a utilização do material de limpeza.;Análise ECRS - Troca de cor simples e complexa;Análise de tempo perdido com expurgo, recorte e recolhimento da purga.;Proposta de alterações para redução de material expurgado (Reduzir material dentro do injetor).;Realizar teste no mini moinho com a purga do EVA para ver o comportamento do material.;Criar mapa de raciocínio da troca de cor;Levantamento de ganhos. | T30: 732.63
A31: DoKMHOwn7UCOR_vLrOHv3mQAHbad | B31: MOI - Tegad / Célula de Layout | C31: =_xlfn.XLOOKUP(A31,Tarefas!A:A,Tarefas!C:C) -> MOI, MOA, MODS | D31: Redução de 50 efetivos MOA, MOI e MODS | E31: Em andamento | F31: Importante | G31: William Kennedy Rodrigues Lopes;Charliane Batista de Alencar | H31: Charliane Batista de Alencar | I31: 2026-07-17 | K31: 2026-07-13 | M31: false | P31: 4/7 | Q31: Levantamento da situação atual;Apresentar e validar com a gestão;Mapear todas as atividades realizadas na área e funções;Lançar FAP;Testar nova proposta de dimensionamento;Verificar possíveis melhorias ou automações de processos;Nova proposta de dimensionamento | S31: Link Apresentação: https://canva.link/h3vnpu6cgzovy20 | T31: 451.23
A32: HXKuxw-cBUepbRalBZSt1mQAKYct | B32: Credenciamento - Programa de Melhorias | C32: =_xlfn.XLOOKUP(A32,Tarefas!A:A,Tarefas!C:C) -> Programa de Melhorias | D32: Atingir 85% de aderência no Programa de Melhorias | E32: Concluída | F32: Média | G32: Leonardo Costa da Silva | H32: Leonardo Costa da Silva | I32: 2026-07-17 | J32: 2026-07-22 | M32: false | N32: 2026-07-24 | O32: Leonardo Costa da Silva | P32: 2/2 | Q32: Reunião para montagem do Plano de Credenciamento do Programa de Melhorias;Estruturar o conteúdo de Treinamento para o Público de Preparadores ate Supervisão | S32: Foi criado o Manual com o objetivo de conduzir o conteudo para TReinamento para o Publico, abordando sobre o programa de Melhorias, o seu funcionamento, bem como, o planejamento da cerimônia de premiação. | T32: 475.39
A33: V0yIkFtIWEOskxThXpxkY2QAM3ON | B33: Padronização das Embalagens | C33: =_xlfn.XLOOKUP(A33,Tarefas!A:A,Tarefas!C:C) -> Padronizações/Certificações | E33: Não iniciado | F33: Média | G33: Leonardo Costa da Silva | H33: Leonardo Costa da Silva | I33: 2026-07-17 | J33: 2026-08-31 | M33: false | P33: 0/4 | Q33: Mobiliários - Crato;Mobiliarios - Fortaleza;Criação do material de apresentação da Hora da Excelência - Padronização das Embalagens;Mobiliários - Sobral | T33: 396.3
A34: CX98n3yEK0mDhVfC_Fi1J2QAHMG- | B34: Padronização das Salas de Tintas | C34: =_xlfn.XLOOKUP(A34,Tarefas!A:A,Tarefas!C:C) -> Padronizações/Certificações | E34: Não iniciado | F34: Média | H34: Leonardo Costa da Silva | I34: 2026-07-17 | M34: false | T34: 102.4
A35: hiwXVtGDc0-i01bBHDNL72QANeXx | B35: Padronização do Tingimento | C35: =_xlfn.XLOOKUP(A35,Tarefas!A:A,Tarefas!C:C) -> Padronizações/Certificações | E35: Não iniciado | F35: Média | H35: Leonardo Costa da Silva | I35: 2026-07-17 | M35: false | T35: 960.52
A36: ZdZflJXSmkK-wVFOke3F5GQAP5-z | B36: [Semana 27-31/07] Automação de atividades de Organização do Programa de Melhorias | C36: =_xlfn.XLOOKUP(A36,Tarefas!A:A,Tarefas!C:C) -> Programa de Melhorias | E36: Em andamento | F36: Média | G36: Thiago Roberto Andrade Aguiar | H36: Leonardo Costa da Silva | I36: 2026-07-17 | J36: 2026-07-31 | M36: true | P36: 1/5 | Q36: Automatizar montagem da apresentação do Programa de Melhorias;Analise dos arquivos e dos fluxos para viabilizar automação;Automatizar montagem dos Certificados;Automatizar Convite dos Premiados e Convite Oficial para Gerencias do Programa de Melhorias;Criação dos arquivos do material de planejamento em pasta para automação | T36: 503.93
A37: Yvny0_yZ00u0pFkafmUt9mQAFqat | B37: Criar operação de aplicar rolinho curvado logo pequeno | C37: =_xlfn.XLOOKUP(A37,Tarefas!A:A,Tarefas!C:C) -> MTM/Impressão 3D | E37: Concluída | F37: Média | G37: Leonardo Galdino de Oliveira | H37: Leonardo Galdino de Oliveira | I37: 2026-07-17 | J37: 2026-07-24 | K37: 2026-07-20 | M37: false | N37: 2026-07-30 | O37: Leonardo Galdino de Oliveira | T37: 618.85
A38: zuLDstg9b0efs3su_Ph4fGQAIxsY | B38: Montar apresentação para treinamento novo dosador | C38: =_xlfn.XLOOKUP(A38,Tarefas!A:A,Tarefas!C:C) -> Padronizações/Certificações | E38: Não iniciado | F38: Média | G38: Leonardo Galdino de Oliveira | H38: Leonardo Galdino de Oliveira | I38: 2026-07-17 | J38: 2026-07-24 | K38: 2026-07-20 | M38: true | T38: 194.13
A39: VielfIXtXEiR6oY1QY6E5GQABVwj | B39: [Semana 20-24/07] Criação dos Famílias - Serigrafia Fábrica 05 | C39: =_xlfn.XLOOKUP(A39,Tarefas!A:A,Tarefas!C:C) -> RPA | E39: Concluída | F39: Urgente | G39: Nalbert de Matos Vieira | H39: Nalbert de Matos Vieira | I39: 2026-07-17 | J39: 2026-07-24 | K39: 2026-07-01 | M39: false | N39: 2026-07-23 | O39: Nalbert de Matos Vieira | P39: 5/5 | Q39: Levantar dados de processo de Serigrafia da Fábrica 05;Criar bases de famílias e gráficos para visualização da distribuição das Famílias;Analisar os padrões p/lacas/hr dos modelos para criar os ranges das Famílias;Levantar dados de PQP;Analisar os padrões pares/hr dos modelos para criar os ranges das Famílias | T39: 505.12
A40: qDcgfgf80kykqSwwa8PPaWQAFFo8 | B40: Projeto TR Cabine de Pintura Manual | C40: =_xlfn.XLOOKUP(A40,Tarefas!A:A,Tarefas!C:C) -> SMED | D40: Redução de 50 efetivos MOA, MOI e MODS | E40: Em andamento | F40: Importante | G40: Francisco Romulo de Aguiar | I40: 2026-07-18 | J40: 2026-08-31 | M40: false | P40: 0/3 | Q40: Confecção de bombas TS7 (nec. 32/ feito 18);Replicação para TS6 (nec. 26);Replicação para TS1 (nec. 12) | T40: 107.76
...

Sheet Tarefas
A1: Identificação da tarefa | B1: Nome da tarefa | D1: Categoria | E1: Meta | F1: Status | G1: Prioridade | H1: Atribuído a | I1: Criado por | J1: Criado em | K1: Data de conclusão | L1: Data de início | M1: É Recorrente | N1: Atrasados | O1: Concluído em | P1: Concluída por | Q1: Itens concluídos da lista de verificação | R1: Itens da lista de verificação | S1: Rótulos | T1: Notas
A2: mHYaQDYxrUiQ7uHDBJV_CGQAA0Bm | B2: Lançar melhoria do bimestre | C2: Programa de Melhorias | D2: KIfHiHgMjUeezxBeVZXLlmQABdnJ | F2: Não iniciado | G2: Média | H2: 63dd591c-960d-4c36-ad48-5b9197dc40ea;p_lylMOxR0ykz-6CgdD7JGQABhqd;3a4654ae-d002-45f0-a510-5a3d7e37c058;13401436-5972-4968-9178-08d3bcd592a4;8c3f18d2-9083-4819-8529-3d7d7f9bfbda | I2: 63dd591c-960d-4c36-ad48-5b9197dc40ea | J2: 2026-08-06 | K2: 2026-10-05 | N2: false | Q2: 0/10 | R2: Rômulo ;Charliane;Thiago Roberto;Martins;Leonardo Galdino;Kennedy;Leonardo Costa;Eduarda;Daniel Viana;Alan Vilela
A3: epEHIZFoYEawEMf2UmdnO2QAEl9u | B3: Lançar melhoria do bimestre | C3: Programa de Melhorias | D3: KIfHiHgMjUeezxBeVZXLlmQABdnJ | F3: Concluída | G3: Média | H3: 63dd591c-960d-4c36-ad48-5b9197dc40ea;p_lylMOxR0ykz-6CgdD7JGQABhqd;3a4654ae-d002-45f0-a510-5a3d7e37c058;13401436-5972-4968-9178-08d3bcd592a4;8c3f18d2-9083-4819-8529-3d7d7f9bfbda | I3: c40cc4cc-bdb3-454f-a193-cf3e59051c09 | J3: 2026-07-17 | K3: 2026-08-05 | N3: false | O3: 2026-08-06 | P3: 63dd591c-960d-4c36-ad48-5b9197dc40ea | Q3: 7/10 | R3: Rômulo ;Charliane;Thiago Roberto;Martins;Leonardo Galdino;Kennedy;Leonardo Costa;Eduarda;Daniel Viana;Alan Vilela
A4: 7SBLlTg6NUODyqgmnqwBnmQAPYN6 | B4: Lançar melhoria do bimestre | C4: Programa de Melhorias | D4: KIfHiHgMjUeezxBeVZXLlmQABdnJ | F4: Concluída | G4: Média | H4: 63dd591c-960d-4c36-ad48-5b9197dc40ea;b12ce1b5-2aa7-4f1d-b43a-272d90aabbe2;p_lylMOxR0ykz-6CgdD7JGQABhqd;3a4654ae-d002-45f0-a510-5a3d7e37c058;13401436-5972-4968-9178-08d3bcd592a4;8c3f18d2-9083-4819-8529-3d7d7f9bfbda | I4: c40cc4cc-bdb3-454f-a193-cf3e59051c09 | J4: 2026-07-17 | K4: 2026-04-05 | N4: false | O4: 2026-07-17 | P4: c40cc4cc-bdb3-454f-a193-cf3e59051c09 | Q4: 0/6 | R4: Rômulo ;Charliane;Martins;Kennedy;Douglas;Jennifer
A5: DRYwgOUmRUOgKzjzalMjq2QAAtiM | B5: Lançar melhoria do bimestre | C5: Programa de Melhorias | D5: KIfHiHgMjUeezxBeVZXLlmQABdnJ | F5: Concluída | G5: Média | H5: 63dd591c-960d-4c36-ad48-5b9197dc40ea;b12ce1b5-2aa7-4f1d-b43a-272d90aabbe2;p_lylMOxR0ykz-6CgdD7JGQABhqd;3a4654ae-d002-45f0-a510-5a3d7e37c058;13401436-5972-4968-9178-08d3bcd592a4;8c3f18d2-9083-4819-8529-3d7d7f9bfbda | I5: c40cc4cc-bdb3-454f-a193-cf3e59051c09 | J5: 2026-07-17 | K5: 2026-02-05 | N5: false | O5: 2026-07-17 | P5: c40cc4cc-bdb3-454f-a193-cf3e59051c09 | Q5: 0/6 | R5: Rômulo ;Charliane;Martins;Kennedy;Douglas;Jennifer
A6: F1LFUkS0RUu3Ibi25ZzRWWQAJj2X | B6: Lançar melhoria do bimestre | C6: Programa de Melhorias | D6: KIfHiHgMjUeezxBeVZXLlmQABdnJ | F6: Concluída | G6: Média | H6: 63dd591c-960d-4c36-ad48-5b9197dc40ea;b12ce1b5-2aa7-4f1d-b43a-272d90aabbe2;p_lylMOxR0ykz-6CgdD7JGQABhqd;3a4654ae-d002-45f0-a510-5a3d7e37c058;13401436-5972-4968-9178-08d3bcd592a4;8c3f18d2-9083-4819-8529-3d7d7f9bfbda | I6: c40cc4cc-bdb3-454f-a193-cf3e59051c09 | J6: 2026-07-17 | K6: 2025-12-05 | N6: false | O6: 2026-07-17 | P6: c40cc4cc-bdb3-454f-a193-cf3e59051c09 | Q6: 0/6 | R6: Rômulo ;Charliane;Martins;Kennedy;Douglas;Jennifer
A7: uQH-ZMJsr0CX1CPaui9Al2QAA1wN | B7: Lançar melhoria do bimestre | C7: Programa de Melhorias | D7: KIfHiHgMjUeezxBeVZXLlmQABdnJ | F7: Concluída | G7: Média | H7: 63dd591c-960d-4c36-ad48-5b9197dc40ea;b12ce1b5-2aa7-4f1d-b43a-272d90aabbe2;p_lylMOxR0ykz-6CgdD7JGQABhqd;3a4654ae-d002-45f0-a510-5a3d7e37c058;13401436-5972-4968-9178-08d3bcd592a4;8c3f18d2-9083-4819-8529-3d7d7f9bfbda | I7: c40cc4cc-bdb3-454f-a193-cf3e59051c09 | J7: 2026-07-17 | K7: 2025-10-05 | N7: false | O7: 2026-07-17 | P7: c40cc4cc-bdb3-454f-a193-cf3e59051c09 | Q7: 0/6 | R7: Rômulo ;Charliane;Martins;Kennedy;Douglas;Jennifer
A8: txeRybaODEq_PH978neS1mQAGaS0 | B8: Lançar melhoria do bimestre | C8: Programa de Melhorias | D8: KIfHiHgMjUeezxBeVZXLlmQABdnJ | F8: Concluída | G8: Média | H8: 63dd591c-960d-4c36-ad48-5b9197dc40ea;b12ce1b5-2aa7-4f1d-b43a-272d90aabbe2;p_lylMOxR0ykz-6CgdD7JGQABhqd;3a4654ae-d002-45f0-a510-5a3d7e37c058;13401436-5972-4968-9178-08d3bcd592a4;8c3f18d2-9083-4819-8529-3d7d7f9bfbda | I8: c40cc4cc-bdb3-454f-a193-cf3e59051c09 | J8: 2026-07-17 | K8: 2025-08-08 | N8: false | O8: 2026-07-17 | P8: c40cc4cc-bdb3-454f-a193-cf3e59051c09 | Q8: 0/6 | R8: Rômulo ;Charliane;Martins;Kennedy;Douglas;Jennifer
A9: tygljY6P00iU4kfls2vKV2QAG4Zo | B9: Lançar melhoria do bimestre | C9: Programa de Melhorias | D9: KIfHiHgMjUeezxBeVZXLlmQABdnJ | F9: Concluída | G9: Média | H9: 63dd591c-960d-4c36-ad48-5b9197dc40ea;b12ce1b5-2aa7-4f1d-b43a-272d90aabbe2;p_lylMOxR0ykz-6CgdD7JGQABhqd;3a4654ae-d002-45f0-a510-5a3d7e37c058;13401436-5972-4968-9178-08d3bcd592a4;8c3f18d2-9083-4819-8529-3d7d7f9bfbda | I9: c40cc4cc-bdb3-454f-a193-cf3e59051c09 | J9: 2026-07-17 | K9: 2024-12-05 | N9: false | O9: 2026-07-17 | P9: c40cc4cc-bdb3-454f-a193-cf3e59051c09 | Q9: 0/6 | R9: Rômulo ;Charliane;Martins;Kennedy;Douglas;Jennifer
A10: 22BLBarPRUGDpRVdEMXK-WQAIPMG | B10: Lançar melhoria do bimestre | C10: Programa de Melhorias | D10: KIfHiHgMjUeezxBeVZXLlmQABdnJ | F10: Concluída | G10: Média | H10: 63dd591c-960d-4c36-ad48-5b9197dc40ea;b12ce1b5-2aa7-4f1d-b43a-272d90aabbe2;p_lylMOxR0ykz-6CgdD7JGQABhqd;3a4654ae-d002-45f0-a510-5a3d7e37c058;13401436-5972-4968-9178-08d3bcd592a4;8c3f18d2-9083-4819-8529-3d7d7f9bfbda | I10: c40cc4cc-bdb3-454f-a193-cf3e59051c09 | J10: 2024-07-05 | K10: 2024-10-31 | N10: false | O10: 2026-07-17 | P10: c40cc4cc-bdb3-454f-a193-cf3e59051c09 | Q10: 0/6 | R10: Rômulo ;Charliane;Martins;Kennedy;Douglas;Jennifer
A11: XyQwFCHhokWxK8Qtp4qmkmQADVuN | B11: Fazer auditoria nos postos de trabalho dos lançamentos | C11: Tarefas Antigas | D11: KIfHiHgMjUeezxBeVZXLlmQABdnJ | F11: Concluída | G11: Média | H11: b12ce1b5-2aa7-4f1d-b43a-272d90aabbe2 | I11: c40cc4cc-bdb3-454f-a193-cf3e59051c09 | J11: 2024-07-25 | K11: 2024-08-30 | N11: false | O11: 2024-09-05 | P11: b12ce1b5-2aa7-4f1d-b43a-272d90aabbe2 | Q11: 4/4 | R11: Gerar laudo dos postos de trabalho e enviar para os envolvidos ;Registrar condições dos postos com fotos ;Analisar postos nos pilares de P5.0 e Ergonomia ;Passar nas linhas produtivas dos lançamentos | S11: Rotina
A12: Hl4x_KZhpkyOUlv5RxATVGQAM31J | B12: Criar as documentações do TEGAD dentro matrix | C12: Tarefas Antigas | D12: KIfHiHgMjUeezxBeVZXLlmQABdnJ | F12: Concluída | G12: Média | H12: vrAXgpRmkkiXVCuPMVArUmQAPEty | I12: c40cc4cc-bdb3-454f-a193-cf3e59051c09 | J12: 2024-07-25 | K12: 2024-08-02 | N12: false | O12: 2024-08-10 | P12: vrAXgpRmkkiXVCuPMVArUmQAPEty
A13: UjbIJMabvEC4WDGe9hiHvWQAK3Mj | B13: Criar as documentações dos montadores de layout dentro do matrix | C13: Tarefas Antigas | D13: KIfHiHgMjUeezxBeVZXLlmQABdnJ | F13: Concluída | G13: Média | H13: vrAXgpRmkkiXVCuPMVArUmQAPEty | I13: c40cc4cc-bdb3-454f-a193-cf3e59051c09 | J13: 2024-07-25 | K13: 2024-09-13 | N13: false | O13: 2026-07-17 | P13: c40cc4cc-bdb3-454f-a193-cf3e59051c09
A14: OxRSVcPgZEuV9LODx_vat2QAPkqZ | B14: Work sampling no processo de chamada ativa do PS7 | C14: Tarefas Antigas | D14: KIfHiHgMjUeezxBeVZXLlmQABdnJ | F14: Concluída | G14: Média | H14: 10FemLyfzUaLyDeuyzZepmQACfMU;p_lylMOxR0ykz-6CgdD7JGQABhqd | I14: c40cc4cc-bdb3-454f-a193-cf3e59051c09 | J14: 2024-07-25 | K14: 2024-08-23 | N14: false | O14: 2024-08-20 | P14: 10FemLyfzUaLyDeuyzZepmQACfMU | Q14: 4/4 | R14: Gerar um gráfico com os dados de percurso com maior repetição ;Registrar os percursos realizados de movimentação dos operadores ;Acompanhar o processo ;Anotar as ocorrências ou divergências do processo
A15: kTIeuZuHKk6LutwStQOPmWQAKOcl | B15: Cadastro de pessoas treinadas aplicativo. | C15: Tarefas Antigas | D15: KIfHiHgMjUeezxBeVZXLlmQABdnJ | F15: Concluída | G15: Média | H15: 10FemLyfzUaLyDeuyzZepmQACfMU;vrAXgpRmkkiXVCuPMVArUmQAPEty | I15: 10FemLyfzUaLyDeuyzZepmQACfMU | J15: 2024-07-25 | K15: 2024-08-23 | N15: false | O15: 2024-08-20 | P15: 10FemLyfzUaLyDeuyzZepmQACfMU | T15: Cadastrar listas de pessoas treinadas no aplicativo.
A16: HgnLevcgA0qC8e0NaziGdmQAAQrK | B16: Atualização planilhas SMED e criação de boletim. | C16: Tarefas Antigas | D16: KIfHiHgMjUeezxBeVZXLlmQABdnJ | F16: Concluída | G16: Média | H16: 10FemLyfzUaLyDeuyzZepmQACfMU;3a4654ae-d002-45f0-a510-5a3d7e37c058 | I16: 10FemLyfzUaLyDeuyzZepmQACfMU | J16: 2024-08-12 | K16: 2024-08-23 | N16: false | O16: 2024-08-20 | P16: 10FemLyfzUaLyDeuyzZepmQACfMU
A17: xZIuz0fqHEKGRIVvx_CjpGQAApIE | B17: Desenho | C17: Tarefas Antigas | D17: KIfHiHgMjUeezxBeVZXLlmQABdnJ | F17: Concluída | G17: Média | H17: vrAXgpRmkkiXVCuPMVArUmQAPEty | I17: vrAXgpRmkkiXVCuPMVArUmQAPEty | J17: 2024-08-13 | K17: 2024-08-16 | N17: false | O17: 2024-08-13 | P17: vrAXgpRmkkiXVCuPMVArUmQAPEty | Q17: 3/3 | R17: Desenho da Mesa Posto de trabalho F3;Desenho do Layout F3-F4;Desenho do Layout Peças Técnicas
A18: lDsMV28xPka_W5yxSGhSB2QAJ3v7 | B18: Atualização planilha dos indicadores | C18: Tarefas Antigas | D18: KIfHiHgMjUeezxBeVZXLlmQABdnJ | F18: Concluída | G18: Média | H18: 10FemLyfzUaLyDeuyzZepmQACfMU;vrAXgpRmkkiXVCuPMVArUmQAPEty | I18: vrAXgpRmkkiXVCuPMVArUmQAPEty | J18: 2024-08-20 | K18: 2024-08-21 | N18: false | O18: 2024-08-22 | P18: vrAXgpRmkkiXVCuPMVArUmQAPEty
A19: 8ZiKOBm8V0W1aszegn2HImQAO_b_ | B19: Atualizar checklist kaizen, ver com RH cadastro de pessoas treinadas em Kaizen. | C19: Tarefas Antigas | D19: KIfHiHgMjUeezxBeVZXLlmQABdnJ | F19: Concluída | G19: Média | H19: 10FemLyfzUaLyDeuyzZepmQACfMU;vrAXgpRmkkiXVCuPMVArUmQAPEty | I19: 10FemLyfzUaLyDeuyzZepmQACfMU | J19: 2024-08-20 | K19: 2024-08-21 | N19: false | O19: 2024-08-21 | P19: 10FemLyfzUaLyDeuyzZepmQACfMU
A20: H1uUhGXRGU-77B3fs6q8LmQANBpP | B20: Organização materiais MEG | C20: Tarefas Antigas | D20: KIfHiHgMjUeezxBeVZXLlmQABdnJ | F20: Concluída | G20: Média | H20: 10FemLyfzUaLyDeuyzZepmQACfMU;vrAXgpRmkkiXVCuPMVArUmQAPEty | I20: 10FemLyfzUaLyDeuyzZepmQACfMU | J20: 2024-08-20 | K20: 2024-09-12 | N20: false | O20: 2026-07-17 | P20: c40cc4cc-bdb3-454f-a193-cf3e59051c09
A21: 1jM1QpSMA02fNwk_HDPi_mQAKDS8 | B21: Estudo Sala Impressão Digital | C21: Tarefas Antigas | D21: KIfHiHgMjUeezxBeVZXLlmQABdnJ | F21: Concluída | G21: Média | H21: 10FemLyfzUaLyDeuyzZepmQACfMU | I21: 10FemLyfzUaLyDeuyzZepmQACfMU | J21: 2024-08-20 | K21: 2024-09-18 | N21: false | O21: 2026-07-17 | P21: c40cc4cc-bdb3-454f-a193-cf3e59051c09
A22: cQO-fezfA0eUz3P6IidJkGQABDk8 | B22: Organizar evento de melhorias | C22: Tarefas Antigas | D22: KIfHiHgMjUeezxBeVZXLlmQABdnJ | F22: Concluída | G22: Média | H22: b12ce1b5-2aa7-4f1d-b43a-272d90aabbe2 | I22: c40cc4cc-bdb3-454f-a193-cf3e59051c09 | J22: 2024-09-27 | K22: 2024-09-24 | N22: false | O22: 2024-09-27 | P22: c40cc4cc-bdb3-454f-a193-cf3e59051c09 | Q22: 5/5 | R22: Organizar o espaço de eventos ;Montar apresentação do evento ;Listar os dados dos premiados (Calçados e informações gerais);Levantar dados das avaliações de percepção. ;Treinar a apresentação
A23: SZ2NF2FBAE-UeRtXURXbLmQANNYa | B23: Passada Horizontal no TS6 | C23: Tarefas Antigas | D23: KIfHiHgMjUeezxBeVZXLlmQABdnJ | F23: Concluída | G23: Média | H23: b12ce1b5-2aa7-4f1d-b43a-272d90aabbe2 | I23: c40cc4cc-bdb3-454f-a193-cf3e59051c09 | J23: 2024-09-27 | K23: 2024-09-27 | N23: false | O23: 2024-09-27 | P23: c40cc4cc-bdb3-454f-a193-cf3e59051c09
A24: DjnKbRcTlEar2AF5aYS1g2QAJm8W | B24: Passada Horizontal TS7 | C24: Tarefas Antigas | D24: KIfHiHgMjUeezxBeVZXLlmQABdnJ | F24: Concluída | G24: Média | H24: b12ce1b5-2aa7-4f1d-b43a-272d90aabbe2 | I24: c40cc4cc-bdb3-454f-a193-cf3e59051c09 | J24: 2024-09-27 | K24: 2024-09-25 | N24: false | O24: 2024-09-27 | P24: c40cc4cc-bdb3-454f-a193-cf3e59051c09
A25: LQZZqn7VwUm8GsQfpC4GhGQADMSP | B25: MOI - Movimentadores de Caixas Montagem | C25: =_xlfn.XLOOKUP(D25,Buckets!A:A,Buckets!B:B) -> MOI, MOA, MODS | D25: QKOg4Hdgj0ivgeBuZ62ybmQAI-jH | E25: UIsKR4azC0aIhKUlTIZKCWQAAOHD | F25: Em andamento | G25: Importante | H25: 8c3f18d2-9083-4819-8529-3d7d7f9bfbda | I25: 8c3f18d2-9083-4819-8529-3d7d7f9bfbda | J25: 2026-07-17 | K25: 2026-07-24 | L25: 2026-07-06 | N25: true | Q25: 6/8 | R25: Validar com a gestão;Determinar padrões da operações;Testar nova proposta;Verificar possíveis propostas de melhorias ou automações;Avaliar durante uma semana dimensionamento pro fator X Padrão / aglutinado;Lançar FAP;Criar nova proposta de dimensionamento;Levantar situação atual | S25: Crato
A26: NkewH3A-5Eail--FODKxU2QAH1YF | B26: Otimização Setup Matriz EVA | C26: =_xlfn.XLOOKUP(D26,Buckets!A:A,Buckets!B:B) -> SMED | D26: 1XwoBpXjJ02mmuVIAeaTAGQAGr4T | E26: CPyA7_JXT0Ot246svFbgKWQADc9O | F26: Não iniciado | G26: Média | H26: 63dd591c-960d-4c36-ad48-5b9197dc40ea;07a2aff1-4a07-48ba-8ada-daf14a19fd85 | I26: 63dd591c-960d-4c36-ad48-5b9197dc40ea | J26: 2026-07-17 | K26: 2026-08-31 | L26: 2026-07-20 | N26: false | Q26: 5/9 | R26: Acompanhar definição do carrinho compra ou confecção junto a fábrica;Análise de ganho para transformação das matrizes em troca rápida (Vagner).;Análise de setups Matriz. (20 à 24/07);Acompanhamento de implantação do Simon.;Teste de carrinho com capacidade para matrizes de entrada e saída.;Fazer analise do custo da estufa ligada o dia todo (Setups por maquina e por dia);Teste de pré aquecimento de matriz em setups reais.;Análise do fluxo de programação do EVA.;Montar material para reunião com Igor (sobre a estufa e moer purga)
A27: sNUu7Jc6NkyzqxvlG4HlcGQANkch | B27: Cerimônia de Premiação do Programa de Melhorias | C27: =_xlfn.XLOOKUP(D27,Buckets!A:A,Buckets!B:B) -> Programa de Melhorias | D27: NHhoi0Q460Owj98eJ_OOMmQANgsZ | F27: Em andamento | G27: Média | H27: 05f35150-a826-4040-9362-c540d816ffd0 | I27: 05f35150-a826-4040-9362-c540d816ffd0 | J27: 2026-07-17 | K27: 2026-12-31 | N27: false | Q27: 1/4 | R27: Cerimônia de Premiação - Bimestre Set/Out 2026;Cerimônia de Premiação - Bimestre Jul/Ago 2026;Cerimônia de Premiação - Bimestre Mai/Jun 2026;Cerimônia de Premiação - Bimestre Nov/Dez 2026
A28: Rs5Oc-Bkx02tuG9Y-sk0lGQAMxXl | B28: MOI - Auxiliar de Matrizaria | C28: =_xlfn.XLOOKUP(D28,Buckets!A:A,Buckets!B:B) -> MOI, MOA, MODS | D28: QKOg4Hdgj0ivgeBuZ62ybmQAI-jH | E28: UIsKR4azC0aIhKUlTIZKCWQAAOHD | F28: Em andamento | G28: Importante | H28: 8c3f18d2-9083-4819-8529-3d7d7f9bfbda | I28: 8c3f18d2-9083-4819-8529-3d7d7f9bfbda | J28: 2026-07-17 | K28: 2026-07-22 | L28: 2026-07-06 | N28: true | Q28: 9/10 | R28: Validar com a gestão;Tabulação de dados e classificação das atividades;Acompanhar turno B;Apresentar a gerência e coordenação;Verificar possíveis propostas de melhorias, transferências ou otimização de atividades;Colocar em teste para avaliar;Proposta de novo dimensionamento;Verificar com Kleilson a decisão de alterar dimensionamento, conforme avaliação no físico;Lançar FAP;Acompanhamento turno A (07/07 e 09/07) | S28: Crato
A29: t8_qJepIiUqnTdiC4yZkT2QAI7ze | B29: MOI - Matrizeiro | C29: =_xlfn.XLOOKUP(D29,Buckets!A:A,Buckets!B:B) -> MOI, MOA, MODS | D29: QKOg4Hdgj0ivgeBuZ62ybmQAI-jH | E29: UIsKR4azC0aIhKUlTIZKCWQAAOHD | F29: Não iniciado | G29: Importante | I29: 8c3f18d2-9083-4819-8529-3d7d7f9bfbda | J29: 2026-07-17 | N29: false | Q29: 0/8 | R29: Tabulação de dados e classificação das atividades;Proposta de novo dimensionamento;Colocar em teste para avaliar;Validar com a gestão;Acompanhamento turno A;Acompanhar turno B;Lançar FAP;Verificar possíveis propostas de melhorias, transferências ou otimização de atividades | S29: Crato
A30: XD1eWNDN_ECyHQuAr9pQImQAJevi | B30: SMED Setup de Cor EVA | C30: =_xlfn.XLOOKUP(D30,Buckets!A:A,Buckets!B:B) -> SMED | D30: 1XwoBpXjJ02mmuVIAeaTAGQAGr4T | E30: CPyA7_JXT0Ot246svFbgKWQADc9O | F30: Não iniciado | G30: Média | H30: 63dd591c-960d-4c36-ad48-5b9197dc40ea;07a2aff1-4a07-48ba-8ada-daf14a19fd85 | I30: 63dd591c-960d-4c36-ad48-5b9197dc40ea | J30: 2026-07-17 | K30: 2026-10-31 | N30: false | Q30: 5/7 | R30: Análise da troca de cor sem a utilização do material de limpeza.;Análise ECRS - Troca de cor simples e complexa;Análise de tempo perdido com expurgo, recorte e recolhimento da purga.;Proposta de alterações para redução de material expurgado (Reduzir material dentro do injetor).;Realizar teste no mini moinho com a purga do EVA para ver o comportamento do material.;Criar mapa de raciocínio da troca de cor;Levantamento de ganhos.
A31: DoKMHOwn7UCOR_vLrOHv3mQAHbad | B31: MOI - Tegad / Célula de Layout | C31: =_xlfn.XLOOKUP(D31,Buckets!A:A,Buckets!B:B) -> MOI, MOA, MODS | D31: QKOg4Hdgj0ivgeBuZ62ybmQAI-jH | E31: UIsKR4azC0aIhKUlTIZKCWQAAOHD | F31: Em andamento | G31: Importante | H31: 3a4654ae-d002-45f0-a510-5a3d7e37c058;8c3f18d2-9083-4819-8529-3d7d7f9bfbda | I31: 8c3f18d2-9083-4819-8529-3d7d7f9bfbda | J31: 2026-07-17 | L31: 2026-07-13 | N31: false | Q31: 4/7 | R31: Levantamento da situação atual;Apresentar e validar com a gestão;Mapear todas as atividades realizadas na área e funções;Lançar FAP;Testar nova proposta de dimensionamento;Verificar possíveis melhorias ou automações de processos;Nova proposta de dimensionamento | T31: Link Apresentação: https://canva.link/h3vnpu6cgzovy20
A32: HXKuxw-cBUepbRalBZSt1mQAKYct | B32: Credenciamento - Programa de Melhorias | C32: =_xlfn.XLOOKUP(D32,Buckets!A:A,Buckets!B:B) -> Programa de Melhorias | D32: NHhoi0Q460Owj98eJ_OOMmQANgsZ | E32: _TclC5XyU0itQqOSRgoOa2QAB9Fw | F32: Concluída | G32: Média | H32: 05f35150-a826-4040-9362-c540d816ffd0 | I32: 05f35150-a826-4040-9362-c540d816ffd0 | J32: 2026-07-17 | K32: 2026-07-22 | N32: false | O32: 2026-07-24 | P32: 05f35150-a826-4040-9362-c540d816ffd0 | Q32: 2/2 | R32: Reunião para montagem do Plano de Credenciamento do Programa de Melhorias;Estruturar o conteúdo de Treinamento para o Público de Preparadores ate Supervisão | T32: Foi criado o Manual com o objetivo de conduzir o conteudo para TReinamento para o Publico, abordando sobre o programa de Melhorias, o seu funcionamento, bem como, o planejamento da cerimônia de premiação.
A33: V0yIkFtIWEOskxThXpxkY2QAM3ON | B33: Padronização das Embalagens | C33: =_xlfn.XLOOKUP(D33,Buckets!A:A,Buckets!B:B) -> Padronizações/Certificações | D33: jcA3eTZpVESyCtCrwdC8t2QAAqf5 | F33: Não iniciado | G33: Média | H33: 05f35150-a826-4040-9362-c540d816ffd0 | I33: 05f35150-a826-4040-9362-c540d816ffd0 | J33: 2026-07-17 | K33: 2026-08-31 | N33: false | Q33: 0/4 | R33: Mobiliários - Crato;Mobiliarios - Fortaleza;Criação do material de apresentação da Hora da Excelência - Padronização das Embalagens;Mobiliários - Sobral
A34: CX98n3yEK0mDhVfC_Fi1J2QAHMG- | B34: Padronização das Salas de Tintas | C34: =_xlfn.XLOOKUP(D34,Buckets!A:A,Buckets!B:B) -> Padronizações/Certificações | D34: jcA3eTZpVESyCtCrwdC8t2QAAqf5 | F34: Não iniciado | G34: Média | I34: 05f35150-a826-4040-9362-c540d816ffd0 | J34: 2026-07-17 | N34: false
A35: hiwXVtGDc0-i01bBHDNL72QANeXx | B35: Padronização do Tingimento | C35: =_xlfn.XLOOKUP(D35,Buckets!A:A,Buckets!B:B) -> Padronizações/Certificações | D35: jcA3eTZpVESyCtCrwdC8t2QAAqf5 | F35: Não iniciado | G35: Média | I35: 05f35150-a826-4040-9362-c540d816ffd0 | J35: 2026-07-17 | N35: false
A36: ZdZflJXSmkK-wVFOke3F5GQAP5-z | B36: [Semana 27-31/07] Automação de atividades de Organização do Programa de Melhorias | C36: =_xlfn.XLOOKUP(D36,Buckets!A:A,Buckets!B:B) -> Programa de Melhorias | D36: NHhoi0Q460Owj98eJ_OOMmQANgsZ | F36: Em andamento | G36: Média | H36: 9686d721-f970-4664-808d-2b7eccd6564a | I36: 05f35150-a826-4040-9362-c540d816ffd0 | J36: 2026-07-17 | K36: 2026-07-31 | N36: true | Q36: 1/5 | R36: Automatizar montagem da apresentação do Programa de Melhorias;Analise dos arquivos e dos fluxos para viabilizar automação;Automatizar montagem dos Certificados;Automatizar Convite dos Premiados e Convite Oficial para Gerencias do Programa de Melhorias;Criação dos arquivos do material de planejamento em pasta para automação
A37: Yvny0_yZ00u0pFkafmUt9mQAFqat | B37: Criar operação de aplicar rolinho curvado logo pequeno | C37: =_xlfn.XLOOKUP(D37,Buckets!A:A,Buckets!B:B) -> MTM/Impressão 3D | D37: 68oi7tmPFkWnLtIUxxbIyGQAGAus | F37: Concluída | G37: Média | H37: 1c74a3a3-f72d-417f-97b2-b50d886d5068 | I37: 1c74a3a3-f72d-417f-97b2-b50d886d5068 | J37: 2026-07-17 | K37: 2026-07-24 | L37: 2026-07-20 | N37: false | O37: 2026-07-30 | P37: 1c74a3a3-f72d-417f-97b2-b50d886d5068
A38: zuLDstg9b0efs3su_Ph4fGQAIxsY | B38: Montar apresentação para treinamento novo dosador | C38: =_xlfn.XLOOKUP(D38,Buckets!A:A,Buckets!B:B) -> Padronizações/Certificações | D38: jcA3eTZpVESyCtCrwdC8t2QAAqf5 | F38: Não iniciado | G38: Média | H38: 1c74a3a3-f72d-417f-97b2-b50d886d5068 | I38: 1c74a3a3-f72d-417f-97b2-b50d886d5068 | J38: 2026-07-17 | K38: 2026-07-24 | L38: 2026-07-20 | N38: true
A39: VielfIXtXEiR6oY1QY6E5GQABVwj | B39: [Semana 20-24/07] Criação dos Famílias - Serigrafia Fábrica 05 | C39: =_xlfn.XLOOKUP(D39,Buckets!A:A,Buckets!B:B) -> RPA | D39: rMSwZXAoc0e0KRod7mGv3mQAO_ax | F39: Concluída | G39: Urgente | H39: dfffd270-6981-4011-8fa1-759e71d9f99e | I39: dfffd270-6981-4011-8fa1-759e71d9f99e | J39: 2026-07-17 | K39: 2026-07-24 | L39: 2026-07-01 | N39: false | O39: 2026-07-23 | P39: dfffd270-6981-4011-8fa1-759e71d9f99e | Q39: 5/5 | R39: Levantar dados de processo de Serigrafia da Fábrica 05;Criar bases de famílias e gráficos para visualização da distribuição das Famílias;Analisar os padrões p/lacas/hr dos modelos para criar os ranges das Famílias;Levantar dados de PQP;Analisar os padrões pares/hr dos modelos para criar os ranges das Famílias
A40: qDcgfgf80kykqSwwa8PPaWQAFFo8 | B40: Projeto TR Cabine de Pintura Manual | C40: =_xlfn.XLOOKUP(D40,Buckets!A:A,Buckets!B:B) -> SMED | D40: 1XwoBpXjJ02mmuVIAeaTAGQAGr4T | E40: UIsKR4azC0aIhKUlTIZKCWQAAOHD | F40: Em andamento | G40: Importante | H40: 63dd591c-960d-4c36-ad48-5b9197dc40ea | I40: fd56df57-6763-4283-b5e9-97b57478fb7a | J40: 2026-07-18 | K40: 2026-08-31 | N40: false | Q40: 0/3 | R40: Confecção de bombas TS7 (nec. 32/ feito 18);Replicação para TS6 (nec. 26);Replicação para TS1 (nec. 12)
...

Sheet Metas
A1: ID da Meta | B1: Nome da meta | C1: Status | D1: Prioridade | E1: Data de início | F1: Data de término | G1: Tarefas conectadas | H1: Notas
A2: _TclC5XyU0itQqOSRgoOa2QAB9Fw | B2: Atingir 85% de aderência no Programa de Melhorias | C2: No prazo | D2: 5 | G2: Credenciamento - Programa de Melhorias
A3: CPyA7_JXT0Ot246svFbgKWQADc9O | B3: Redução de 25% do tempo de setup de matriz e 15% setup de cor na injeção de EVA | C3: No prazo | D3: 5 | G3: Otimização Setup Matriz EVA;SMED Setup de Cor EVA
A4: UIsKR4azC0aIhKUlTIZKCWQAAOHD | B4: Redução de 50 efetivos MOA, MOI e MODS | C4: No prazo | D4: 5 | F4: 2026-11-06 | G4: MOI - Movimentadores de Caixas Montagem;MOI - Auxiliar de Matrizaria;MOI - Matrizeiro;MOI - Tegad / Célula de Layout;Projeto TR Cabine de Pintura Manual;Projeto 02 - Dimensionamento dos Trocadores de Layout Fáb. 06;Projeto 02 - Dimensionamento dos Trocadores de Layout Fáb. 07;Projeto 02 - Dimensionamento dos Trocadores de Layout Crato;Projeto 02 - Dimensionamento dos Trocadores de Layout Fáb. 01;Projeto 01 - Dimensionamento dos Reguladores de Telas

Sheet Buckets
A1: ID de Bucket | B1: Nome do Bucket
A2: QKOg4Hdgj0ivgeBuZ62ybmQAI-jH | B2: MOI, MOA, MODS
A3: 1XwoBpXjJ02mmuVIAeaTAGQAGr4T | B3: SMED
A4: rMSwZXAoc0e0KRod7mGv3mQAO_ax | B4: RPA
A5: 68oi7tmPFkWnLtIUxxbIyGQAGAus | B5: MTM/Impressão 3D
A6: jcA3eTZpVESyCtCrwdC8t2QAAqf5 | B6: Padronizações/Certificações
A7: NHhoi0Q460Owj98eJ_OOMmQANgsZ | B7: Programa de Melhorias
A8: hzRxxQYRwUmjMGwIgIiUvGQABgeH | B8: Logística
A9: KIfHiHgMjUeezxBeVZXLlmQABdnJ | B9: Melhorias do Bimestre | C9: Programa de Melhorias | D9: Tarefas Antigas
A10: X4rT7zMEMUaVaYHT5_sXtWQAMXMy | B10: Pendências Fechamento de Indicadores

Sheet Usuários
A1: ID do Usuário | B1: Nome do usuário | C1: Email
A2: 63dd591c-960d-4c36-ad48-5b9197dc40ea | B2: Francisco Romulo de Aguiar | C2: romulo.aguiar@grendene.com.br
A3: 3a4654ae-d002-45f0-a510-5a3d7e37c058 | B3: William Kennedy Rodrigues Lopes | C3: william.lopes@grendene.com.br
A4: 13401436-5972-4968-9178-08d3bcd592a4 | B4: Francisco Martins da Silva | C4: martins.silva@grendene.com.br
A5: 8c3f18d2-9083-4819-8529-3d7d7f9bfbda | B5: Charliane Batista de Alencar | C5: charlianeb.alencar@grendene.com.br
A6: c40cc4cc-bdb3-454f-a193-cf3e59051c09 | B6: Fernanda Sousa Araujo | C6: fernanda.araujo@grendene.com.br
A7: 07a2aff1-4a07-48ba-8ada-daf14a19fd85 | B7: Aliny Kelly De Assis Rufino | C7: aliny.rufino@grendene.com.br
A8: 05f35150-a826-4040-9362-c540d816ffd0 | B8: Leonardo Costa da Silva | C8: silva.leonardo@grendene.com.br
A9: 9686d721-f970-4664-808d-2b7eccd6564a | B9: Thiago Roberto Andrade Aguiar | C9: roberto.aguiar@grendene.com.br
A10: 1c74a3a3-f72d-417f-97b2-b50d886d5068 | B10: Leonardo Galdino de Oliveira | C10: leonardo.oliveir@grendene.com.br
A11: dfffd270-6981-4011-8fa1-759e71d9f99e | B11: Nalbert de Matos Vieira | C11: nalbert.vieira@grendene.com.br
A12: 58a13380-4d77-41ea-9406-2f4cb7f6bd8c | B12: Daniel Viana de Carvalho | C12: daniel.carvalho@grendene.com.br
A13: da78ac04-7f85-4d9a-afb4-9b5876e9062b | B13: Alan Feitosa Vilela | C13: alan.vilela@grendene.com.br

Sheet Planilha1
A1: Descrição | B1: Sigla
A2: Melhorias do Bimestre | B2: MEL/BI
A3: MOI, MOA, MODS | B3: KPI
A4: SMED | B4: SMED
A5: Programa de Melhorias | B5: PG/MEL
A6: Padronizações/Certificações | B6: PD/CERT
A7: MTM/Impressão 3D | B7: MTM/3D
A8: RPA | B8: RPA
A9: Logística | B9: LOG
A10: Pendências Fechamento de Indicadores | B10: PEND
